<mujoco model="CR3URDF">
  <compiler angle="radian" meshdir="assets" autolimits="true"/>

  <option timestep="0.002" integrator="implicitfast" cone="elliptic" impratio="10"/>
  
  <default>
    <default class="cr3">
      <material specular="0.5" shininess="0.25"/>
      <joint damping="2" armature="0.05" limited="true" axis="0 0 1"/>
      <general dyntype="none" gaintype="fixed" biastype="affine" forcerange="-200 200"/>
      <geom friction="0.8 0.1 0.1"/>
      <default class="visual">
        <geom type="mesh" contype="0" conaffinity="0" group="2" rgba="0.95 0.95 0.95 1"/>
      </default>
      <default class="collision">
        <geom type="mesh" group="3" rgba="0.5 0.5 0.5 1"/>
        <!-- <geom type="mesh" contype="0" conaffinity="0" group="3" rgba="0.5 0.5 0.5 1"/> -->
      </default>
    </default>
  </default>
  <asset>
    <mesh name="base_link" file="base_link.STL"/>
    <mesh name="Link1" file="Link1.STL"/>
    <mesh name="Link2" file="Link2.STL"/>
    <mesh name="Link3" file="Link3.STL"/>
    <mesh name="Link4" file="Link4.STL"/>
    <mesh name="Link5" file="Link5.STL"/>
    <mesh name="Link6" file="Link6.STL"/>
  </asset>
  <worldbody>
    <!-- <geom name="floor" type="plane" size="2 2 0.1" rgba="0.8 0.8 0.8 1" contype="1" conaffinity="1"/>
    <light pos="0 0 2" dir="0 0 -1" diffuse="1 1 1" specular="0.3 0.3 0.3"/>
    <camera name="fixed" pos="1.2 -1.2 0.9" quat="0.8 0.3 0.1 0.5"/> -->
    <body name="base_link" childclass="cr3">
      <geom mesh="base_link" class="visual" type="mesh"/>
      <geom mesh="base_link" class="collision" type="mesh"/>
      <body name="Link1" pos="0 0 0.1283">
        <inertial pos="-3.68658e-05 -0.00394517 0.00364038" quat="0.668079 0.224285 -0.228154 0.671798" mass="1.31101" diaginertia="0.00217669 0.00202531 0.00164384"/>
        <joint name="joint1" pos="0 0 0" axis="0 0 1" range="-3.14 3.14"/>
        <geom type="mesh" mesh="Link1" class="visual"/>
        <body name="Link2" quat="0.499998 0.5 0.5 -0.500002">
          <inertial pos="-0.129235 1.44054e-05 0.133174" quat="0.483434 0.51644 0.516337 0.482677" mass="3.40044" diaginertia="0.0063233 0.00578813 0.00450009"/>
          <joint name="joint2" pos="0 0 0" axis="0 0 1" range="-3.14 3.14"/>
          <geom type="mesh" mesh="Link2" class="visual"/>
          <body name="Link3" pos="-0.274 0 0">
            <inertial pos="-0.119823 8.63344e-08 0.00998766" quat="0.432122 0.559713 0.559721 0.432092" mass="2.21449" diaginertia="0.00313635 0.0028872 0.00232519"/>
            <joint name="joint3" pos="0 0 0" axis="0 0 1" range="-3.14 3.14"/>
            <geom type="mesh" mesh="Link3" class="visual"/>
            <body name="Link4" pos="-0.23 0 0.1283" quat="0.707105 0 0 -0.707108">
              <inertial pos="1.7468e-07 0.00345224 -0.0028731" quat="0.601412 0.371834 -0.371869 0.601462" mass="0.842273" diaginertia="0.00106054 0.0010039 0.000726821"/>
              <joint name="joint4" pos="0 0 0" axis="0 0 1" range="-3.14 3.14"/>
              <geom type="mesh" mesh="Link4" class="visual"/>
              <body name="Link5" pos="0 -0.116 0" quat="0.707105 0.707108 0 0">
                <inertial pos="-1.74604e-07 -0.00333192 -0.00286781" quat="0.37287 0.600892 -0.600772 0.372788" mass="0.843693" diaginertia="0.00106485 0.00100855 0.000728263"/>
                <joint name="joint5" pos="0 0 0" axis="0 0 1" range="-3.14 3.14"/>
                <geom type="mesh" mesh="Link5" class="visual"/>
                <body name="Link6" pos="0 0.105 0" quat="0.707105 -0.707108 0 0">
                  <inertial pos="-5.77233e-07 0.000270131 -0.0201387" quat="-0.00177703 0.707105 -0.000182648 0.707107" mass="0.159409" diaginertia="0.000131911 8.35925e-05 8.29484e-05"/>
                  <joint name="joint6" pos="0 0 0" axis="0 0 1" range="-3.14 3.14"/>
                  <geom type="mesh" mesh="Link6" class="visual"/>
                  <geom type="mesh" mesh="Link6" class="collision"/>
                  <site name="tcp" pos="0 0 0.08" size="0.01" rgba="1 0 0 1"/>
                </body>
                <geom type="mesh" mesh="Link5" class="collision"/>
              </body>
              <geom type="mesh" mesh="Link4" class="collision"/>
            </body>
            <geom type="mesh" mesh="Link3" class="collision"/>
          </body>
          <geom type="mesh" mesh="Link2" class="collision"/>
        </body>
        <geom type="mesh" mesh="Link1" class="collision"/>
      </body>
    </body>
  </worldbody>
  <actuator>
    <!-- <motor name="test_motor1" joint="joint1" ctrlrange="-2 2" forcerange="-50 50"/> -->
    <general class="cr3" name="act_joint1" joint="joint1" gainprm="300" biasprm="0 -300 -30" ctrlrange="-3.14 3.14"/>
    <general class="cr3" name="act_joint2" joint="joint2" gainprm="400" biasprm="0 -400 -40" ctrlrange="-3.14 3.14"/>
    <general class="cr3" name="act_joint3" joint="joint3" gainprm="300" biasprm="0 -300 -30" ctrlrange="-3.14 3.14"/>
    <general class="cr3" name="act_joint4" joint="joint4" gainprm="250" biasprm="0 -250 -25" ctrlrange="-3.14 3.14"/>
    <general class="cr3" name="act_joint5" joint="joint5" gainprm="200" biasprm="0 -200 -20" ctrlrange="-3.14 3.14"/>
    <general class="cr3" name="act_joint6" joint="joint6" gainprm="150" biasprm="0 -150 -15" ctrlrange="-3.14 3.14"/>
  </actuator>

  <keyframe>
    <key name="home" qpos="0.0982 -0.525 0.0419 -1.22 -0.838 0" ctrl="0.0982 -0.525 0.0419 -1.22 -0.838 0"/>
  </keyframe>

  <contact>
    <exclude body1="base_link" body2="Link1"/>
    <!-- <exclude body1="Link1"     body2="Link2"/>
    <exclude body1="Link2"     body2="Link3"/>
    <exclude body1="Link3"     body2="Link4"/>
    <exclude body1="Link4"     body2="Link5"/>
    <exclude body1="Link5"     body2="Link6"/> -->
 </contact>

</mujoco>
